Workbook
Name ALPHA_DURABLES: Constants_NonDisaggregated!$M$5:$O$18
Name ALPHA_NON_DURABLES: Constants_NonDisaggregated!$M$37:$M$50
Name ALPHA_QUAIDS_AUSTRIA: Beta_QUAIDS_3!$C$5:$H$65
Name ALPHA_QUAIDS_BELGIUM: Beta_QUAIDS_3!$C$66:$H$126
Name ALPHA_QUAIDS_BULGARIA: Beta_QUAIDS_3!$C$127:$H$187
Name ALPHA_QUAIDS_CHINA: Beta_QUAIDS_3!$C$1713:$H$1773
Name ALPHA_QUAIDS_CROATIA: Beta_QUAIDS_3!$C$188:$H$248
Name ALPHA_QUAIDS_CYPRUS: Beta_QUAIDS_3!$C$249:$H$309
Name ALPHA_QUAIDS_CZECH_REPUBLIC: Beta_QUAIDS_3!$C$310:$H$370
Name ALPHA_QUAIDS_DENMARK: Beta_QUAIDS_3!$C$371:$H$431
Name ALPHA_QUAIDS_EASOC: Beta_QUAIDS_3!$C$1774:$H$1834
Name ALPHA_QUAIDS_ESTONIA: Beta_QUAIDS_3!$C$432:$H$492
Name ALPHA_QUAIDS_FINLAND: Beta_QUAIDS_3!$C$493:$H$553
Name ALPHA_QUAIDS_FRANCE: Beta_QUAIDS_3!$C$554:$H$614
Name ALPHA_QUAIDS_GERMANY: Beta_QUAIDS_3!$C$615:$H$675
Name ALPHA_QUAIDS_GREECE: Beta_QUAIDS_3!$C$676:$H$736
Name ALPHA_QUAIDS_HUNGARY: Beta_QUAIDS_3!$C$737:$H$797
Name ALPHA_QUAIDS_INDIA: Beta_QUAIDS_3!$C$1835:$H$1895
Name ALPHA_QUAIDS_IRELAND: Beta_QUAIDS_3!$C$798:$H$858
Name ALPHA_QUAIDS_ITALY: Beta_QUAIDS_3!$C$859:$H$919
Name ALPHA_QUAIDS_LATAM: Beta_QUAIDS_3!$C$1896:$H$1956
Name ALPHA_QUAIDS_LATVIA: Beta_QUAIDS_3!$C$920:$H$980
Name ALPHA_QUAIDS_LITHUANIA: Beta_QUAIDS_3!$C$981:$H$1041
Name ALPHA_QUAIDS_LROW: Beta_QUAIDS_3!$C$2079:$H$2139
Name ALPHA_QUAIDS_LUXEMBOURG: Beta_QUAIDS_3!$C$1042:$H$1102
Name ALPHA_QUAIDS_MALTA: Beta_QUAIDS_3!$C$1103:$H$1163
Name ALPHA_QUAIDS_NETHERLANDS: Beta_QUAIDS_3!$C$1164:$H$1224
Name ALPHA_QUAIDS_POLAND: Beta_QUAIDS_3!$C$1225:$H$1285
Name ALPHA_QUAIDS_PORTUGAL: Beta_QUAIDS_3!$C$1286:$H$1346
Name ALPHA_QUAIDS_ROMANIA: Beta_QUAIDS_3!$C$1347:$H$1407
Name ALPHA_QUAIDS_RUSSIA: Beta_QUAIDS_3!$C$1957:$H$2017
Name ALPHA_QUAIDS_SLOVAKIA: Beta_QUAIDS_3!$C$1408:$H$1468
Name ALPHA_QUAIDS_SLOVENIA: Beta_QUAIDS_3!$C$1469:$H$1529
Name ALPHA_QUAIDS_SPAIN: Beta_QUAIDS_3!$C$1530:$H$1590
Name ALPHA_QUAIDS_SWEDEN: Beta_QUAIDS_3!$C$1591:$H$1651
Name ALPHA_QUAIDS_UK: Beta_QUAIDS_3!$C$1652:$H$1712
Name ALPHA_QUAIDS_USMCA: Beta_QUAIDS_3!$C$2018:$H$2078
Name BASE_CONSUMPTION_COICOP: Consumption_COICOP!$B$5:$T$39
Name BASE_GROSS_OPERATING_SURPLUS: BASE_Operating_surplus_tot!$A$5:$AI$5
Name BASE_PRICE_COICOP: BASE_Price_COICOP!$B$5:$T$39
Name BASE_SOCIAL_BENEFITS: BASE_Social_benefits!$A$5:$AI$5
Name BASE_TAX_INCOME_CORPORATIONS: BASE_Tax_Income_corp!$A$5:$AI$5
Name BETA_APPLIANCES: Beta_Appliances_1!$B$5:$BJ$39
Name BETA_HH_TRANSPORT: Beta_hh_transport_1!$B$5:$BJ$39
Name BETA_HOUSING: Beta_Housing_1!$B$5:$BJ$39
Name BETA_NON_DURABLES: Beta_NonDurables_1!$B$5:$BJ$39
Name BETA_QUAIDS_AUSTRIA_H1: BETA_QUAIDS_1!$D$5:$I$10
Name BETA_QUAIDS_AUSTRIA_H10: BETA_QUAIDS_1!$D$59:$I$64
Name BETA_QUAIDS_AUSTRIA_H11: BETA_QUAIDS_1!$D$65:$I$70
Name BETA_QUAIDS_AUSTRIA_H12: BETA_QUAIDS_1!$D$71:$I$76
Name BETA_QUAIDS_AUSTRIA_H13: BETA_QUAIDS_1!$D$77:$I$82
Name BETA_QUAIDS_AUSTRIA_H14: BETA_QUAIDS_1!$D$83:$I$88
Name BETA_QUAIDS_AUSTRIA_H15: BETA_QUAIDS_1!$D$89:$I$94
Name BETA_QUAIDS_AUSTRIA_H16: BETA_QUAIDS_1!$D$95:$I$100
Name BETA_QUAIDS_AUSTRIA_H17: BETA_QUAIDS_1!$D$101:$I$106
Name BETA_QUAIDS_AUSTRIA_H18: BETA_QUAIDS_1!$D$107:$I$112
Name BETA_QUAIDS_AUSTRIA_H19: BETA_QUAIDS_1!$D$113:$I$118
Name BETA_QUAIDS_AUSTRIA_H2: BETA_QUAIDS_1!$D$11:$I$16
Name BETA_QUAIDS_AUSTRIA_H20: BETA_QUAIDS_1!$D$119:$I$124
Name BETA_QUAIDS_AUSTRIA_H21: BETA_QUAIDS_1!$D$125:$I$130

Sheet Disclaimer
A1: Disclaimers
A2: Household data (only countries with household heterogeneity) have been compiled by disaggregating national accounts macro-aggregates with household micro-data structures. More specifically, the micro-data sources used come from Eurostat, Household Budget Survey 2010 and 2015 and European Union Statistics on Income and Living Conditions 2010, 2011, 2015 and 2016 for consumption- and income-related variables and from the European Central Bank, Eurosystem Household Finance and Consumption Survey 2010 and 2014 for wealth-related variables. The responsibility for all conclusions drawn from the data lies entirely with the authors. The results published and the related observations and analyses may not correspond to the results or analyses of the data producers. The data provided preclude the respondents’ identification and do not show confidential data. The micro-economic structures used are derived from a synthetic dataset of fused surveys, with the European Union Statistics on Income and Living Conditions survey as the recipient survey. The number of observations from which each micro-economic structure is derived is given below. Eurostat distinguishes three situations according to the number of observations (unweighted sample): less than 20 observations, from 20 to 49 observations, and more than 49 observations. Micro-economic structures based on less than 20 observations are removed and treated as missing values, while those based on from 20 to 49 observations and on more than 49 observations are flagged for information only. When micro-economic structures are not available, those of the most similar country in terms of macro-economic indicators are used.
A15: Individual flags (applies to all household-related information in the model for countries with heterogeneous households).
A16: Household | B16: BEL | C16: BGR | D16: CYP | E16: CZE | F16: DEU | G16: DNK | H16: ESP | I16: EST | J16: FIN | K16: FRA | L16: GRC | M16: HRV | N16: HUN | O16: IRL | P16: LTU | Q16: LUX | R16: LVA | S16: POL | T16: PRT | U16: SVK | V16: SWE
A17: INCOME1_DENSE_SINGLE | B17: More than 49 observations | C17: More than 49 observations | D17: More than 49 observations | E17: More than 49 observations | F17: More than 49 observations | G17: More than 49 observations | H17: More than 49 observations | I17: More than 49 observations | J17: More than 49 observations | K17: More than 49 observations | L17: More than 49 observations | M17: More than 49 observations | N17: More than 49 observations | O17: More than 49 observations | P17: More than 49 observations | Q17: 20-49 observations | R17: More than 49 observations | S17: More than 49 observations | T17: More than 49 observations | U17: More than 49 observations | V17: More than 49 observations
A18: INCOME1_DENSE_SINGLEWCHILDREN | B18: Less than 20 observations | C18: Less than 20 observations | D18: Less than 20 observations | E18: Less than 20 observations | F18: 20-49 observations | G18: Less than 20 observations | H18: 20-49 observations | I18: Less than 20 observations | J18: Less than 20 observations | K18: 20-49 observations | L18: Less than 20 observations | M18: Less than 20 observations | N18: Less than 20 observations | O18: 20-49 observations | P18: Less than 20 observations | Q18: Less than 20 observations | R18: 20-49 observations | S18: Less than 20 observations | T18: Less than 20 observations | U18: Less than 20 observations | V18: Less than 20 observations
A19: INCOME1_DENSE_COUPLE | B19: More than 49 observations | C19: More than 49 observations | D19: More than 49 observations | E19: More than 49 observations | F19: More than 49 observations | G19: More than 49 observations | H19: More than 49 observations | I19: More than 49 observations | J19: More than 49 observations | K19: More than 49 observations | L19: More than 49 observations | M19: More than 49 observations | N19: More than 49 observations | O19: More than 49 observations | P19: More than 49 observations | Q19: 20-49 observations | R19: More than 49 observations | S19: More than 49 observations | T19: More than 49 observations | U19: More than 49 observations | V19: More than 49 observations
A20: INCOME1_DENSE_COUPLEWCHILDREN | B20: More than 49 observations | C20: More than 49 observations | D20: More than 49 observations | E20: More than 49 observations | F20: More than 49 observations | G20: 20-49 observations | H20: More than 49 observations | I20: More than 49 observations | J20: More than 49 observations | K20: More than 49 observations | L20: More than 49 observations | M20: 20-49 observations | N20: 20-49 observations | O20: More than 49 observations | P20: 20-49 observations | Q20: 20-49 observations | R20: More than 49 observations | S20: More than 49 observations | T20: More than 49 observations | U20: 20-49 observations | V20: 20-49 observations
A21: INCOME1_DENSE_OTHER | B21: 20-49 observations | C21: More than 49 observations | D21: More than 49 observations | E21: 20-49 observations | F21: More than 49 observations | G21: Less than 20 observations | H21: More than 49 observations | I21: More than 49 observations | J21: 20-49 observations | K21: More than 49 observations | L21: More than 49 observations | M21: More than 49 observations | N21: More than 49 observations | O21: 20-49 observations | P21: More than 49 observations | Q21: Less than 20 observations | R21: More than 49 observations | S21: More than 49 observations | T21: More than 49 observations | U21: More than 49 observations | V21: Less than 20 observations
A22: INCOME1_DENSE_OTHERWCHILDREN | B22: 20-49 observations | C22: 20-49 observations | D22: 20-49 observations | E22: Less than 20 observations | F22: 20-49 observations | G22: Less than 20 observations | H22: More than 49 observations | I22: 20-49 observations | J22: 20-49 observations | K22: More than 49 observations | L22: 20-49 observations | M22: 20-49 observations | N22: Less than 20 observations | O22: 20-49 observations | P22: 20-49 observations | Q22: Less than 20 observations | R22: More than 49 observations | S22: 20-49 observations | T22: More than 49 observations | U22: 20-49 observations | V22: Less than 20 observations
A23: INCOME1_SPARSE_SINGLE | B23: More than 49 observations | C23: More than 49 observations | D23: More than 49 observations | E23: More than 49 observations | F23: More than 49 observations | G23: More than 49 observations | H23: More than 49 observations | I23: More than 49 observations | J23: More than 49 observations | K23: More than 49 observations | L23: More than 49 observations | M23: More than 49 observations | N23: More than 49 observations | O23: More than 49 observations | P23: More than 49 observations | Q23: More than 49 observations | R23: More than 49 observations | S23: More than 49 observations | T23: More than 49 observations | U23: More than 49 observations | V23: More than 49 observations
A24: INCOME1_SPARSE_SINGLEWCHILDREN | B24: 20-49 observations | C24: Less than 20 observations | D24: Less than 20 observations | E24: Less than 20 observations | F24: 20-49 observations | G24: Less than 20 observations | H24: Less than 20 observations | I24: Less than 20 observations | J24: 20-49 observations | K24: 20-49 observations | L24: 20-49 observations | M24: Less than 20 observations | N24: 20-49 observations | O24: 20-49 observations | P24: Less than 20 observations | Q24: Less than 20 observations | R24: Less than 20 observations | S24: 20-49 observations | T24: 20-49 observations | U24: Less than 20 observations | V24: 20-49 observations
A25: INCOME1_SPARSE_COUPLE | B25: More than 49 observations | C25: More than 49 observations | D25: More than 49 observations | E25: More than 49 observations | F25: More than 49 observations | G25: More than 49 observations | H25: More than 49 observations | I25: More than 49 observations | J25: More than 49 observations | K25: More than 49 observations | L25: More than 49 observations | M25: More than 49 observations | N25: More than 49 observations | O25: More than 49 observations | P25: More than 49 observations | Q25: More than 49 observations | R25: More than 49 observations | S25: More than 49 observations | T25: More than 49 observations | U25: More than 49 observations | V25: More than 49 observations
A26: INCOME1_SPARSE_COUPLEWCHILDREN | B26: More than 49 observations | C26: More than 49 observations | D26: More than 49 observations | E26: More than 49 observations | F26: More than 49 observations | G26: More than 49 observations | H26: More than 49 observations | I26: More than 49 observations | J26: More than 49 observations | K26: More than 49 observations | L26: More than 49 observations | M26: More than 49 observations | N26: More than 49 observations | O26: More than 49 observations | P26: 20-49 observations | Q26: More than 49 observations | R26: More than 49 observations | S26: More than 49 observations | T26: More than 49 observations | U26: More than 49 observations | V26: More than 49 observations
A27: INCOME1_SPARSE_OTHER | B27: More than 49 observations | C27: More than 49 observations | D27: More than 49 observations | E27: More than 49 observations | F27: More than 49 observations | G27: More than 49 observations | H27: More than 49 observations | I27: More than 49 observations | J27: More than 49 observations | K27: More than 49 observations | L27: More than 49 observations | M27: More than 49 observations | N27: More than 49 observations | O27: More than 49 observations | P27: More than 49 observations | Q27: More than 49 observations | R27: More than 49 observations | S27: More than 49 observations | T27: More than 49 observations | U27: More than 49 observations | V27: More than 49 observations
... A76: INCOME5_SPARSE_OTHERWCHILDREN | B76: 20-49 observations | C76: More than 49 observations | D76: 20-49 observations | E76: More than 49 observations | F76: More than 49 observations | G76: More than 49 observations | H76: More than 49 observations | I76: More than 49 observations | J76: More than 49 observations | K76: More than 49 observations | L76: More than 49 observations | M76: More than 49 observations | N76: More than 49 observations | O76: More than 49 observations | P76: More than 49 observations | Q76: More than 49 observations | R76: 20-49 observations | S76: More than 49 observations | T76: More than 49 observations | U76: More than 49 observations | V76: More than 49 observations

Sheet BASE_Operating_surplus_tot
A4: AUT | B4: BEL | C4: BGR | D4: HRV | E4: CYP | F4: CZE | G4: DNK | H4: EST | I4: FIN | J4: FRA | K4: DEU | L4: GRC | M4: HUN | N4: IRL | O4: ITA | P4: LVA | Q4: LTU | R4: LUX | S4: MLT | T4: NLD | U4: POL | V4: PRT | W4: ROU | X4: SVK | Y4: SVN | Z4: ESP | AA4: SWE | AB4: UK | AC4: China | AD4: EASOC | AE4: India | AF4: LATAM | AG4: Russia | AH4: USMCA | AI4: LROW
A5: 125958.36 | B5: 139807.38 | C5: 18359.497 | D5: 13823.514 | E5: 4761.7769 | F5: 77473.059 | G5: 87261.673 | H5: 8089.2857 | I5: 71795.957 | J5: 720359 | K5: 1132389.5 | L5: 76984.484 | M5: 45158.648 | N5: 147419.3 | O5: 595439.02 | P5: 10802.044 | Q5: 18557.341 | R5: 27123.803 | S5: 4239.1879 | T5: 247168.5 | U5: 195791.92 | V5: 75318.359 | W5: 84673.614 | X5: 37648.507 | Y5: 12463.65 | Z5: 421095.04 | AA5: 169355.35 | AB5: 867771.03 | AC5: 2286534.1 | AD5: 2991951.6 | AE5: 870859.71 | AF5: 1376248.8 | AG5: 459374.04 | AH5: 8132428.8 | AI5: 2597196.7

Sheet BASE_Number_households
B4: INCOME1_DENSE_SINGLE | C4: INCOME1_DENSE_SINGLEWCHILDREN | D4: INCOME1_DENSE_COUPLE | E4: INCOME1_DENSE_COUPLEWCHILDREN | F4: INCOME1_DENSE_OTHER | G4: INCOME1_DENSE_OTHERWCHILDREN | H4: INCOME1_SPARSE_SINGLE | I4: INCOME1_SPARSE_SINGLEWCHILDREN | J4: INCOME1_SPARSE_COUPLE | K4: INCOME1_SPARSE_COUPLEWCHILDREN | L4: INCOME1_SPARSE_OTHER | M4: INCOME1_SPARSE_OTHERWCHILDREN | N4: INCOME2_DENSE_SINGLE | O4: INCOME2_DENSE_SINGLEWCHILDREN | P4: INCOME2_DENSE_COUPLE | Q4: INCOME2_DENSE_COUPLEWCHILDREN | R4: INCOME2_DENSE_OTHER | S4: INCOME2_DENSE_OTHERWCHILDREN | T4: INCOME2_SPARSE_SINGLE | U4: INCOME2_SPARSE_SINGLEWCHILDREN | V4: INCOME2_SPARSE_COUPLE | W4: INCOME2_SPARSE_COUPLEWCHILDREN | X4: INCOME2_SPARSE_OTHER | Y4: INCOME2_SPARSE_OTHERWCHILDREN | Z4: INCOME3_DENSE_SINGLE | AA4: INCOME3_DENSE_SINGLEWCHILDREN | AB4: INCOME3_DENSE_COUPLE | AC4: INCOME3_DENSE_COUPLEWCHILDREN | AD4: INCOME3_DENSE_OTHER | AE4: INCOME3_DENSE_OTHERWCHILDREN | AF4: INCOME3_SPARSE_SINGLE | AG4: INCOME3_SPARSE_SINGLEWCHILDREN | AH4: INCOME3_SPARSE_COUPLE | AI4: INCOME3_SPARSE_COUPLEWCHILDREN | AJ4: INCOME3_SPARSE_OTHER | AK4: INCOME3_SPARSE_OTHERWCHILDREN | AL4: INCOME4_DENSE_SINGLE | AM4: INCOME4_DENSE_SINGLEWCHILDREN | AN4: INCOME4_DENSE_COUPLE | AO4: INCOME4_DENSE_COUPLEWCHILDREN | AP4: INCOME4_DENSE_OTHER | AQ4: INCOME4_DENSE_OTHERWCHILDREN | AR4: INCOME4_SPARSE_SINGLE | AS4: INCOME4_SPARSE_SINGLEWCHILDREN | AT4: INCOME4_SPARSE_COUPLE | AU4: INCOME4_SPARSE_COUPLEWCHILDREN | AV4: INCOME4_SPARSE_OTHER | AW4: INCOME4_SPARSE_OTHERWCHILDREN | AX4: INCOME5_DENSE_SINGLE | AY4: INCOME5_DENSE_SINGLEWCHILDREN | AZ4: INCOME5_DENSE_COUPLE | BA4: INCOME5_DENSE_COUPLEWCHILDREN | BB4: INCOME5_DENSE_OTHER | BC4: INCOME5_DENSE_OTHERWCHILDREN | BD4: INCOME5_SPARSE_SINGLE | BE4: INCOME5_SPARSE_SINGLEWCHILDREN | BF4: INCOME5_SPARSE_COUPLE | BG4: INCOME5_SPARSE_COUPLEWCHILDREN | BH4: INCOME5_SPARSE_OTHER | BI4: INCOME5_SPARSE_OTHERWCHILDREN | BJ4: REPRESENTATIVE_HOUSEHOLD
A5: AUT | B5: 0 | C5: 0 | D5: 0 | E5: 0 | F5: 0 | G5: 0 | H5: 0 | I5: 0 | J5: 0 | K5: 0 | L5: 0 | M5: 0 | N5: 0 | O5: 0 | P5: 0 | Q5: 0 | R5: 0 | S5: 0 | T5: 0 | U5: 0 | V5: 0 | W5: 0 | X5: 0 | Y5: 0 | Z5: 0 | AA5: 0 | AB5: 0 | AC5: 0 | AD5: 0 | AE5: 0 | AF5: 0 | AG5: 0 | AH5: 0 | AI5: 0 | AJ5: 0 | AK5: 0 | AL5: 0 | AM5: 0 | AN5: 0 | AO5: 0 | AP5: 0 | AQ5: 0 | AR5: 0 | AS5: 0 | AT5: 0 | AU5: 0 | AV5: 0 | AW5: 0 | AX5: 0 | AY5: 0 | AZ5: 0 | BA5: 0 | BB5: 0 | BC5: 0 | BD5: 0 | BE5: 0 | BF5: 0 | BG5: 0 | BH5: 0 | BI5: 0 | BJ5: 3742195.6
A6: BEL | B6: 131051.81 | C6: 13025.397 | D6: 71147.156 | E6: 44556.515 | F6: 25558.363 | G6: 12661.382 | H6: 198802.95 | I6: 20498.51 | J6: 209977.52 | K6: 109212.68 | L6: 82077.884 | M6: 34018.791 | N6: 132072.62 | O6: 13143.88 | P6: 71240.558 | Q6: 44645.069 | R6: 26317.042 | S6: 12662.353 | T6: 198665.49 | U6: 21109.159 | V6: 207014.14 | W6: 110388.57 | X6: 82188.333 | Y6: 34516.063 | Z6: 131582.79 | AA6: 12935.314 | AB6: 71960.122 | AC6: 44858.714 | AD6: 26180.462 | AE6: 12767.202 | AF6: 197349.44 | AG6: 20524.515 | AH6: 210600.15 | AI6: 109981.78 | AJ6: 82770.634 | AK6: 34672.986 | AL6: 132063.67 | AM6: 13068.64 | AN6: 71364.92 | AO6: 45251.286 | AP6: 26096.639 | AQ6: 13057.716 | AR6: 199022.64 | AS6: 21731.958 | AT6: 208922.14 | AU6: 109017.1 | AV6: 82291.275 | AW6: 34629.306 | AX6: 130841.11 | AY6: 13493.769 | AZ6: 71600.245 | BA6: 44848.416 | BB6: 26421.494 | BC6: 13289.148 | BD6: 197706.48 | BE6: 20555.857 | BF6: 209606.05 | BG6: 110724.88 | BH6: 82492.873 | BI6: 34607.854 | BJ6: 0
A7: BGR | B7: 79559.944 | C7: 5130.8702 | D7: 70091.21 | E7: 42908.618 | F7: 49663.12 | G7: 18020.654 | H7: 88882.89 | I7: 3770.007 | J7: 90070.258 | K7: 38778.839 | L7: 61026.877 | M7: 36091.22 | N7: 80158.714 | O7: 5065.1559 | P7: 70737.836 | Q7: 43543.201 | R7: 49110.482 | S7: 17773.249 | T7: 89252.897 | U7: 3719.8924 | V7: 90479.547 | W7: 37818.594 | X7: 62249.008 | Y7: 36085.24 | Z7: 79822.59 | AA7: 4974.4763 | AB7: 70532.759 | AC7: 43123.062 | AD7: 50836.8 | AE7: 18651.883 | AF7: 89403.452 | AG7: 4428.5996 | AH7: 89952.062 | AI7: 39760.203 | AJ7: 61064.966 | AK7: 36231.102 | AL7: 80908.263 | AM7: 5335.7242 | AN7: 70204.382 | AO7: 43699.201 | AP7: 49409.789 | AQ7: 18311.427 | AR7: 89020.444 | AS7: 3804.0849 | AT7: 90196.723 | AU7: 39623.382 | AV7: 60966.735 | AW7: 36105.121 | AX7: 80177.49 | AY7: 5637.7734 | AZ7: 70751.813 | BA7: 43642.918 | BB7: 50168.809 | BC7: 18411.088 | BD7: 89375.316 | BE7: 4176.6161 | BF7: 90717.41 | BG7: 39071.981 | BH7: 62157.414 | BI7: 36239.316 | BJ7: 0
A8: HRV | B8: 23110.929 | C8: 494.03593 | D8: 21417.64 | E8: 9294.1181 | F8: 18337.211 | G8: 6140.5692 | H8: 49250.622 | I8: 894.9149 | J8: 52800.709 | K8: 29464.489 | L8: 52658.453 | M8: 29675.3 | N8: 23346.926 | O8: 1060.9049 | P8: 21175.827 | Q8: 9943.4642 | R8: 18477.002 | S8: 6388.3603 | T8: 49050.021 | U8: 815.06019 | V8: 52739.064 | W8: 29415.183 | X8: 52691.526 | Y8: 29453.985 | Z8: 23027.194 | AA8: 1760.938 | AB8: 21591.465 | AC8: 10014.237 | AD8: 18548.567 | AE8: 6366.3342 | AF8: 49685.889 | AG8: 935.84139 | AH8: 52934.287 | AI8: 29590.543 | AJ8: 52716.798 | AK8: 29686.252 | AL8: 23398.655 | AM8: 1223.7654 | AN8: 21306.905 | AO8: 9116.6608 | AP8: 18163.679 | AQ8: 5729.8452 | AR8: 49107.562 | AS8: 889.74471 | AT8: 52143.525 | AU8: 28950.695 | AV8: 52705.922 | AW8: 29307.425 | AX8: 23029.296 | AY8: 1533.6758 | AZ8: 21229.163 | BA8: 9742.0196 | BB8: 18902.041 | BC8: 6988.2911 | BD8: 49402.907 | BE8: 1057.0788 | BF8: 53382.415 | BG8: 30111.091 | BH8: 52785.301 | BI8: 30277.039 | BJ8: 0
A9: CYP | B9: 7851.4287 | C9: 511.53552 | D9: 10602.364 | E9: 5296.6159 | F9: 5218.3218 | G9: 2311.9844 | H9: 4774.6032 | I9: 394.51356 | J9: 9409.7224 | K9: 5788.0239 | L9: 4790.3279 | M9: 3058.3455 | N9: 7818.5238 | O9: 543.39945 | P9: 10913.085 | Q9: 5396.362 | R9: 5436.6678 | S9: 2332.5273 | T9: 4762.1109 | U9: 810.14993 | V9: 9354.691 | W9: 5908.3133 | X9: 4816.0408 | Y9: 3262.8026 | Z9: 7829.9143 | AA9: 516.1325 | AB9: 10885.701 | AC9: 5321.9362 | AD9: 5335.6927 | AE9: 2318.5414 | AF9: 4836.914 | AG9: 653.64796 | AH9: 9442.9767 | AI9: 5875.497 | AJ9: 4840.8728 | AK9: 3232.1417 | AL9: 7866.675 | AM9: 503.98388 | AN9: 10796.18 | AO9: 5493.7497 | AP9: 5346.3264 | AQ9: 2340.3214 | AR9: 4841.8397 | AS9: 501.49537 | AT9: 9377.5015 | AU9: 5812.2541 | AV9: 4790.8024 | AW9: 3190.4779 | AX9: 7895.1582 | AY9: 582.67866 | AZ9: 10844.169 | BA9: 5405.3362 | BB9: 5387.2914 | BC9: 2372.3256 | BD9: 4826.8322 | BE9: 680.13317 | BF9: 9485.7085 | BG9: 5906.3118 | BH9: 4895.056 | BI9: 3391.9322 | BJ9: 0
A10: CZE | B10: 96245.029 | C10: 7815.4273 | D10: 89727.42 | E10: 44030.26 | F10: 34041.721 | G10: 11133.379 | H10: 142078.77 | I10: 12758.079 | J10: 180151.16 | K10: 94019.927 | L10: 96193.349 | M10: 42129.228 | N10: 95891.814 | O10: 8417.1864 | P10: 89339.858 | Q10: 44180.681 | R10: 33443.562 | S10: 11589.071 | T10: 141846.09 | U10: 12954.522 | V10: 180222.89 | W10: 94713.882 | X10: 96341.981 | Y10: 43052.756 | Z10: 96156.717 | AA10: 8513.8311 | AB10: 89867.411 | AC10: 44303.758 | AD10: 34603.077 | AE10: 11200.135 | AF10: 142154.15 | AG10: 13103.435 | AH10: 180617.18 | AI10: 94168.651 | AJ10: 95928.795 | AK10: 42886.762 | AL10: 96325.973 | AM10: 8176.7477 | AN10: 89243.968 | AO10: 43960.689 | AP10: 33974.15 | AQ10: 11218.999 | AR10: 142572.27 | AS10: 12579.854 | AT10: 180184.45 | AU10: 94584.552 | AV10: 96759.314 | AW10: 42908.665 | AX10: 96167.468 | AY10: 9021.5075 | AZ10: 89357.343 | BA10: 44586.612 | BB10: 34194.49 | BC10: 11734.715 | BD10: 142026.73 | BE10: 13586.709 | BF10: 180908.32 | BG10: 94386.989 | BH10: 96366.561 | BI10: 43362.589 | BJ10: 0
A11: DNK | B11: 112172.7 | C11: 7480.0232 | D11: 48710.7 | E11: 27771.661 | F11: 7922.8069 | G11: 4047.9251 | H11: 139843.38 | I11: 11142.641 | J11: 110321.22 | K11: 52103.586 | L11: 22524.69 | M11: 13975.866 | N11: 115550.97 | O11: 9061.3337 | P11: 49819.516 | Q11: 27880.642 | R11: 8205.5577 | S11: 4534.157 | T11: 139494.65 | U11: 11039.347 | V11: 110488.42 | W11: 52219.86 | X11: 21565.352 | Y11: 13537.685 | Z11: 114118.14 | AA11: 6685.2467 | AB11: 49544.296 | AC11: 27884.801 | AD11: 7967.8701 | AE11: 5125.5864 | AF11: 139957.85 | AG11: 10646.784 | AH11: 110451.01 | AI11: 52890.259 | AJ11: 22183.052 | AK11: 14649.511 | AL11: 113603.97 | AM11: 9603.6289 | AN11: 49368.887 | AO11: 27913.696 | AP11: 8139.3204 | AQ11: 4592.9564 | AR11: 140608.36 | AS11: 11403.905 | AT11: 110400.8 | AU11: 52871.217 | AV11: 21948.796 | AW11: 14332.128 | AX11: 113965.22 | AY11: 8790.2675 | AZ11: 49505.601 | BA11: 28073.2 | BB11: 8364.1449 | BC11: 4589.375 | BD11: 140147.75 | BE11: 11705.423 | BF11: 110496.55 | BG11: 52530.078 | BH11: 22512.11 | BI11: 14135.511 | BJ11: 0
A12: EST | B12: 25841.755 | C12: 1661.4498 | D12: 19785.686 | E12: 11494.891 | F12: 7556.5731 | G12: 4290.1199 | H12: 16846.541 | I12: 1174.7034 | J12: 12602.685 | K12: 6770.7906 | L12: 5825.2391 | M12: 3446.5638 | N12: 25997.387 | O12: 1699.1011 | P12: 19738.113 | Q12: 11520.625 | R12: 7807.5277 | S12: 4375.5693 | T12: 16961.58 | U12: 1421.1429 | V12: 12554.184 | W12: 6862.346 | X12: 6035.7593 | Y12: 3476.1689 | Z12: 26272.869 | AA12: 1706.3412 | AB12: 19796.939 | AC12: 11569.291 | AD12: 7596.3723 | AE12: 4286.2524 | AF12: 16884.763 | AG12: 1221.2352 | AH12: 12690.624 | AI12: 6851.3888 | AJ12: 5853.5607 | AK12: 3545.2327 | AL12: 25955.034 | AM12: 1718.6287 | AN12: 19854.321 | AO12: 11471.84 | AP12: 7755.6293 | AQ12: 4290.1417 | AR12: 16916.47 | AS12: 1336.6761 | AT12: 12660.244 | AU12: 6789.0356 | AV12: 5924.0758 | AW12: 3497.5572 | AX12: 25954.954 | AY12: 1769.8891 | AZ12: 19893.941 | BA12: 11607.852 | BB12: 7736.8976 | BC12: 4453.5167 | BD12: 16930.545 | BE12: 1383.5124 | BF12: 12659.662 | BG12: 6846.2389 | BH12: 5937.3652 | BI12: 3495.5774 | BJ12: 0
A13: FIN | B13: 92673.46 | C13: 6084.1465 | D13: 64253.486 | E13: 26630.123 | F13: 8966.1031 | G13: 4749.7568 | H13: 119719.12 | I13: 5688.8968 | J13: 109536.86 | K13: 46925.723 | L13: 19283.296 | M13: 12453.056 | N13: 92710.992 | O13: 6352.5086 | P13: 65639.78 | Q13: 26765.554 | R13: 9210.4259 | S13: 5226.2973 | T13: 120649.4 | U13: 5685.2893 | V13: 109908.81 | W13: 47135.083 | X13: 19332.574 | Y13: 12278.244 | Z13: 92314.274 | AA13: 6114.4492 | AB13: 65099.999 | AC13: 27060.773 | AD13: 9305.5126 | AE13: 4661.3785 | AF13: 120153.91 | AG13: 6096.4784 | AH13: 110332.99 | AI13: 46833.069 | AJ13: 19403.842 | AK13: 12701.844 | AL13: 93109.582 | AM13: 6300.8401 | AN13: 65118.643 | AO13: 26888.122 | AP13: 8995.0964 | AQ13: 4870.1409 | AR13: 120214.81 | AS13: 5897.2212 | AT13: 109822.23 | AU13: 47233.905 | AV13: 19507.984 | AW13: 12478.384 | AX13: 92987.691 | AY13: 6266.4555 | AZ13: 65111.092 | BA13: 26840.428 | BB13: 9350.6621 | BC13: 4939.6264 | BD13: 120341.76 | BE13: 5863.3143 | BF13: 110046.11 | BG13: 47139.219 | BH13: 19189.704 | BI13: 12636.772 | BJ13: 0
A14: FRA | B14: 974368.55 | C14: 93676.743 | D14: 685069.92 | E14: 390761.95 | F14: 205461.77 | G14: 110117.69 | H14: 887452.04 | I14: 101148.87 | J14: 878399.42 | K14: 494859.52 | L14: 272612.25 | M14: 147848.8 | N14: 998736.3 | O14: 98200.503 | P14: 686111.94 | Q14: 391291.63 | R14: 209633.18 | S14: 110183.72 | T14: 885797.47 | U14: 105068.87 | V14: 879567.68 | W14: 496300.14 | X14: 273308.09 | Y14: 145916.79 | Z14: 960785.83 | AA14: 101613.05 | AB14: 683883.67 | AC14: 392330.52 | AD14: 206352.44 | AE14: 110220.04 | AF14: 894614.58 | AG14: 105121.51 | AH14: 879760.14 | AI14: 496236.55 | AJ14: 270731.26 | AK14: 149174.99 | AL14: 986468.07 | AM14: 95363.067 | AN14: 686709.12 | AO14: 392316.47 | AP14: 210319.15 | AQ14: 110970.65 | AR14: 889162.26 | AS14: 99451.171 | AT14: 879881.95 | AU14: 495896.15 | AV14: 271203.53 | AW14: 150041.68 | AX14: 980981.25 | AY14: 99243.634 | AZ14: 686905.35 | BA14: 391999.44 | BB14: 207953.46 | BC14: 110391.9 | BD14: 889773.65 | BE14: 109111.58 | BF14: 879090.81 | BG14: 496697.64 | BH14: 274264.88 | BI14: 148873.73 | BJ14: 0
A15: DEU | B15: 1595675 | C15: 90452.036 | D15: 983546.29 | E15: 296009.97 | F15: 166379.5 | G15: 35389.534 | H15: 1736708.7 | I15: 123865.2 | J15: 1689931.3 | K15: 739425.58 | L15: 544741.19 | M15: 156339.16 | N15: 1594602.7 | O15: 95399.012 | P15: 984159.81 | Q15: 296522.92 | R15: 169093.48 | S15: 39212.329 | T15: 1741172.5 | U15: 123928.23 | V15: 1689575.6 | W15: 737579.42 | X15: 537607.07 | Y15: 162300.95 | Z15: 1594017.6 | AA15: 89649.797 | AB15: 984207.88 | AC15: 298633.89 | AD15: 167539.63 | AE15: 36587.68 | AF15: 1748164.8 | AG15: 123449.51 | AH15: 1687390.6 | AI15: 738872.32 | AJ15: 541926.62 | AK15: 159924.59 | AL15: 1591953.7 | AM15: 90849.628 | AN15: 983863.41 | AO15: 296358.63 | AP15: 168622.96 | AQ15: 38174.713 | AR15: 1735536.8 | AS15: 125666.7 | AT15: 1692501.6 | AU15: 741209.07 | AV15: 541432.18 | AW15: 155674.75 | AX15: 1596161.1 | AY15: 94293.526 | AZ15: 984522.61 | BA15: 298784.59 | BB15: 170034.43 | BC15: 37484.745 | BD15: 1741557.1 | BE15: 123269.36 | BF15: 1691100.9 | BG15: 740373.61 | BH15: 544242.94 | BI15: 165745.55 | BJ15: 0
A16: GRC | B16: 96779.29 | C16: 3756.8336 | D16: 85285.77 | E16: 55018.899 | F16: 70490.102 | G16: 16920.25 | H16: 114913.32 | I16: 4241.8737 | J16: 152358.85 | K16: 83452.051 | L16: 104465 | M16: 35968.407 | N16: 96136.872 | O16: 4009.0026 | P16: 85531.002 | Q16: 54799.254 | R16: 70194.589 | S16: 17495.619 | T16: 114764.81 | U16: 3133.4705 | V16: 152349.93 | W16: 82803.13 | X16: 104449.43 | Y16: 36354.938 | Z16: 96577.22 | AA16: 4078.255 | AB16: 85236.843 | AC16: 54346.291 | AD16: 70948.839 | AE16: 17466.863 | AF16: 115262.64 | AG16: 3717.955 | AH16: 152184.06 | AI16: 82445.425 | AJ16: 104878.62 | AK16: 36319.46 | AL16: 96535.461 | AM16: 3879.1712 | AN16: 85010.119 | AO16: 55251.329 | AP16: 71094.204 | AQ16: 17443.967 | AR16: 115409.13 | AS16: 3918.3341 | AT16: 152434.93 | AU16: 83066.129 | AV16: 104426.97 | AW16: 36626.879 | AX16: 96417.158 | AY16: 4095.7376 | AZ16: 85105.267 | BA16: 54709.227 | BB16: 70749.267 | BC16: 17534.6 | BD16: 114481.1 | BE16: 3509.4667 | BF16: 152356.23 | BG16: 83447.266 | BH16: 104767.98 | BI16: 36414.317 | BJ16: 0
... A39: LROW | B39: 0 | C39: 0 | D39: 0 | E39: 0 | F39: 0 | G39: 0 | H39: 0 | I39: 0 | J39: 0 | K39: 0 | L39: 0 | M39: 0 | N39: 0 | O39: 0 | P39: 0 | Q39: 0 | R39: 0 | S39: 0 | T39: 0 | U39: 0 | V39: 0 | W39: 0 | X39: 0 | Y39: 0 | Z39: 0 | AA39: 0 | AB39: 0 | AC39: 0 | AD39: 0 | AE39: 0 | AF39: 0 | AG39: 0 | AH39: 0 | AI39: 0 | AJ39: 0 | AK39: 0 | AL39: 0 | AM39: 0 | AN39: 0 | AO39: 0 | AP39: 0 | AQ39: 0 | AR39: 0 | AS39: 0 | AT39: 0 | AU39: 0 | AV39: 0 | AW39: 0 | AX39: 0 | AY39: 0 | AZ39: 0 | BA39: 0 | BB39: 0 | BC39: 0 | BD39: 0 | BE39: 0 | BF39: 0 | BG39: 0 | BH39: 0 | BI39: 0 | BJ39: 633760000

Sheet BASE_Social_benefits
A4: AUT | B4: BEL | C4: BGR | D4: HRV | E4: CYP | F4: CZE | G4: DNK | H4: EST | I4: FIN | J4: FRA | K4: DEU | L4: GRC | M4: HUN | N4: IRL | O4: ITA | P4: LVA | Q4: LTU | R4: LUX | S4: MLT | T4: NLD | U4: POL | V4: PRT | W4: ROU | X4: SVK | Y4: SVN | Z4: ESP | AA4: SWE | AB4: UK | AC4: China | AD4: EASOC | AE4: India | AF4: LATAM | AG4: Russia | AH4: USMCA | AI4: LROW
A5: 72243.303 | B5: 78492.97 | C5: 6015.8127 | D5: 7187.3017 | E5: 2733.1753 | F5: 23107.76 | G5: 51439.623 | H5: 2597.5928 | I5: 46112.487 | J5: 483738.97 | K5: 521171.73 | L5: 38877.35 | M5: 16023.809 | N5: 25621.106 | O5: 369372.55 | P5: 2838.0244 | Q5: 4497.9674 | R5: 8805.3203 | S5: 1094.424 | T5: 86842.724 | U5: 68235.734 | V5: 35102.231 | W5: 18775.3 | X5: 12168.366 | Y5: 7302.5954 | Z5: 188893.55 | AA5: 66518.266 | AB5: 398168.19 | AC5: 994231.73 | AD5: 817551.29 | AE5: 182879.94 | AF5: 374968.45 | AG5: 137102.68 | AH5: 2831960.1 | AI5: 682617.12

Sheet BASE_Price_COICOP
B4: HH_HOUSING | C4: HH_APPLIANCES | D4: HH_VEHICLES | E4: HH_ELECTRICITY | F4: HH_GAS | G4: HH_LIQUID_FUELS | H4: HH_SOLID_FUELS | I4: HH_HEAT | J4: HH_FUEL_TRANSPORT | K4: HH_RAILWAY | L4: HH_ROAD | M4: HH_AIR | N4: HH_MARITIME | O4: HH_FOOD | P4: HH_TEXTILES | Q4: HH_FURNITURE_EQUIPMENT | R4: HH_SERVICES | S4: HH_LEISURE | T4: HH_OTHER
A5: AUT | B5: 108.41699 | C5: 125.56626 | D5: 123.60792 | E5: 112.61824 | F5: 142.60035 | G5: 225.65951 | H5: 154.84646 | I5: 116.33614 | J5: 229.4824 | K5: 100.89665 | L5: 100.16766 | M5: 104.7807 | N5: 101.86396 | O5: 185.39031 | P5: 193.57755 | Q5: 156.74703 | R5: 113.99535 | S5: 125.68488 | T5: 116.18727
A6: BEL | B6: 101.81458 | C6: 138.08368 | D6: 116.85905 | E6: 110.41112 | F6: 127.01496 | G6: 177.80093 | H6: 141.00789 | I6: 119.84678 | J6: 178.42025 | K6: 93.631152 | L6: 84.84648 | M6: 100.94122 | N6: 102.34742 | O6: 187.13257 | P6: 192.62499 | Q6: 146.2836 | R6: 105.71398 | S6: 119.84538 | T6: 118.09092
A7: BGR | B7: 117.05639 | C7: 494.3599 | D7: 375.62148 | E7: 114.62009 | F7: 1731.11 | G7: 2100.7644 | H7: 537.3489 | I7: 127.96521 | J7: 2225.5013 | K7: 103.72237 | L7: 104.63168 | M7: 107.02507 | N7: 103.64774 | O7: 315.37754 | P7: 336.13296 | Q7: 365.56952 | R7: 210.25751 | S7: 323.33533 | T7: 270.79232
A8: HRV | B8: 109.38192 | C8: 146.89984 | D8: 139.11488 | E8: 122.99824 | F8: 140.91361 | G8: 198.07384 | H8: 130.75822 | I8: 125.50387 | J8: 200.69625 | K8: 134.58525 | L8: 138.41247 | M8: 100.83155 | N8: 97.464913 | O8: 165.68182 | P8: 177.55179 | Q8: 145.57901 | R8: 114.07847 | S8: 129.89057 | T8: 115.02921
A9: CYP | B9: 111.24987 | C9: 140.39439 | D9: 132.95199 | E9: 120.62949 | F9: 170.63801 | G9: 181.2284 | H9: 130.66177 | I9: 129.99184 | J9: 193.98937 | K9: 92.033085 | L9: 96.640567 | M9: 100.10294 | N9: 100.4072 | O9: 237.76367 | P9: 260.06095 | Q9: 212.2142 | R9: 123.03912 | S9: 132.41136 | T9: 121.96149
A10: CZE | B10: 104.03731 | C10: 108.31642 | D10: 107.60041 | E10: 109.04542 | F10: 114.2821 | G10: 184.05401 | H10: 115.33521 | I10: 109.19605 | J10: 193.99228 | K10: 86.99111 | L10: 84.066441 | M10: 100.91308 | N10: 103.65265 | O10: 170.31825 | P10: 180.74338 | Q10: 125.9971 | R10: 110.58641 | S10: 116.36339 | T10: 108.85613
A11: DNK | B11: 104.28841 | C11: 140.72382 | D11: 162.24063 | E11: 161.31967 | F11: 159.626 | G11: 141.49598 | H11: 135.93815 | I11: 155.72277 | J11: 136.42436 | K11: 97.950812 | L11: 94.534573 | M11: 106.06965 | N11: 103.8402 | O11: 155.83559 | P11: 160.72615 | Q11: 147.97949 | R11: 106.52323 | S11: 130.23306 | T11: 109.26327
A12: EST | B12: 105.75019 | C12: 107.9539 | D12: 121.06407 | E12: 117.25856 | F12: 147.38906 | G12: 184.78068 | H12: 146.18103 | I12: 117.09075 | J12: 188.44191 | K12: 97.637788 | L12: 96.408657 | M12: 100.00516 | N12: 97.672246 | O12: 178.12243 | P12: 185.95605 | Q12: 137.70173 | R12: 109.5472 | S12: 120.10075 | T12: 111.46716
A13: FIN | B13: 104.12045 | C13: 120.42628 | D13: 131.27937 | E13: 122.2366 | F13: 140.79595 | G13: 143.30225 | H13: 134.93613 | I13: 122.3406 | J13: 145.30307 | K13: 100.67907 | L13: 100.11404 | M13: 102.18581 | N13: 100.68291 | O13: 196.58071 | P13: 208.73449 | Q13: 144.87536 | R13: 107.20489 | S13: 122.078 | T13: 113.34047
A14: FRA | B14: 103.51513 | C14: 129.0604 | D14: 133.30803 | E14: 114.1687 | F14: 125.23239 | G14: 179.11923 | H14: 138.85114 | I14: 120.91386 | J14: 181.96758 | K14: 91.3271 | L14: 88.636422 | M14: 104.8826 | N14: 99.619568 | O14: 175.5092 | P14: 183.09315 | Q14: 151.98919 | R14: 109.58799 | S14: 121.70217 | T14: 116.81129
A15: DEU | B15: 103.38738 | C15: 121.64983 | D15: 120.15036 | E15: 122.38722 | F15: 131.24527 | G15: 181.13317 | H15: 127.72961 | I15: 121.61289 | J15: 187.50114 | K15: 95.816054 | L15: 94.1495 | M15: 110.08362 | N15: 101.74958 | O15: 170.53026 | P15: 174.75843 | Q15: 150.44886 | R15: 113.38413 | S15: 125.03111 | T15: 113.77202
A16: GRC | B16: 129.17575 | C16: 1206.9664 | D16: 3824.2623 | E16: 120.26529 | F16: 441.34833 | G16: 699.4996 | H16: 441.64691 | I16: 420.17778 | J16: 676.66363 | K16: 109.85181 | L16: 110.38825 | M16: 102.81291 | N16: 100.00482 | O16: 397.18029 | P16: 456.86203 | Q16: 1002.8052 | R16: 282.1329 | S16: 300.43222 | T16: 462.50712
... A39: LROW | B39: 102.6612 | C39: 121.03006 | D39: 119.73088 | E39: 106.87398 | F39: 134.23844 | G39: 188.32564 | H39: 136.32006 | I39: 115.34969 | J39: 190.24142 | K39: 104.91646 | L39: 104.97157 | M39: 104.75595 | N39: 101.51484 | O39: 125.04664 | P39: 132.72588 | Q39: 124.46045 | R39: 105.71905 | S39: 113.49597 | T39: 107.80199

Sheet BASE_Tax_Income_corp
A4: AUT | B4: BEL | C4: BGR | D4: HRV | E4: CYP | F4: CZE | G4: DNK | H4: EST | I4: FIN | J4: FRA | K4: DEU | L4: GRC | M4: HUN | N4: IRL | O4: ITA | P4: LVA | Q4: LTU | R4: LUX | S4: MLT | T4: NLD | U4: POL | V4: PRT | W4: ROU | X4: SVK | Y4: SVN | Z4: ESP | AA4: SWE | AB4: UK | AC4: China | AD4: EASOC | AE4: India | AF4: LATAM | AG4: Russia | AH4: USMCA | AI4: LROW
A5: 9000.0278 | B5: 15363.48 | C5: 1097.7006 | D5: 590.91423 | E5: 381.26505 | F5: 5967.8058 | G5: 8583.6498 | H5: 470.76423 | I5: 5056.3344 | J5: 64491.796 | K5: 81802.331 | L5: 4441.1626 | M5: 2040.5627 | N5: 7700.1908 | O5: 37198.21 | P5: 431.18587 | Q5: 636.73069 | R5: 2546.4118 | S5: 267.30242 | T5: 21006.685 | U5: 8790.5298 | V5: 6228.362 | W5: 2286.4316 | X5: 3333.6735 | Y5: 631.43254 | Z5: 26363.148 | AA5: 14674.136 | AB5: 68874.047 | AC5: 108163.05 | AD5: 227623.74 | AE5: 15260.505 | AF5: 39499.039 | AG5: 17267.521 | AH5: 453101.15 | AI5: 198546.27

Sheet HH_Property_income_rec
B4: INCOME1_DENSE_SINGLE | C4: INCOME1_DENSE_SINGLEWCHILDREN | D4: INCOME1_DENSE_COUPLE | E4: INCOME1_DENSE_COUPLEWCHILDREN | F4: INCOME1_DENSE_OTHER | G4: INCOME1_DENSE_OTHERWCHILDREN | H4: INCOME1_SPARSE_SINGLE | I4: INCOME1_SPARSE_SINGLEWCHILDREN | J4: INCOME1_SPARSE_COUPLE | K4: INCOME1_SPARSE_COUPLEWCHILDREN | L4: INCOME1_SPARSE_OTHER | M4: INCOME1_SPARSE_OTHERWCHILDREN | N4: INCOME2_DENSE_SINGLE | O4: INCOME2_DENSE_SINGLEWCHILDREN | P4: INCOME2_DENSE_COUPLE | Q4: INCOME2_DENSE_COUPLEWCHILDREN | R4: INCOME2_DENSE_OTHER | S4: INCOME2_DENSE_OTHERWCHILDREN | T4: INCOME2_SPARSE_SINGLE | U4: INCOME2_SPARSE_SINGLEWCHILDREN | V4: INCOME2_SPARSE_COUPLE | W4: INCOME2_SPARSE_COUPLEWCHILDREN | X4: INCOME2_SPARSE_OTHER | Y4: INCOME2_SPARSE_OTHERWCHILDREN | Z4: INCOME3_DENSE_SINGLE | AA4: INCOME3_DENSE_SINGLEWCHILDREN | AB4: INCOME3_DENSE_COUPLE | AC4: INCOME3_DENSE_COUPLEWCHILDREN | AD4: INCOME3_DENSE_OTHER | AE4: INCOME3_DENSE_OTHERWCHILDREN | AF4: INCOME3_SPARSE_SINGLE | AG4: INCOME3_SPARSE_SINGLEWCHILDREN | AH4: INCOME3_SPARSE_COUPLE | AI4: INCOME3_SPARSE_COUPLEWCHILDREN | AJ4: INCOME3_SPARSE_OTHER | AK4: INCOME3_SPARSE_OTHERWCHILDREN | AL4: INCOME4_DENSE_SINGLE | AM4: INCOME4_DENSE_SINGLEWCHILDREN | AN4: INCOME4_DENSE_COUPLE | AO4: INCOME4_DENSE_COUPLEWCHILDREN | AP4: INCOME4_DENSE_OTHER | AQ4: INCOME4_DENSE_OTHERWCHILDREN | AR4: INCOME4_SPARSE_SINGLE | AS4: INCOME4_SPARSE_SINGLEWCHILDREN | AT4: INCOME4_SPARSE_COUPLE | AU4: INCOME4_SPARSE_COUPLEWCHILDREN | AV4: INCOME4_SPARSE_OTHER | AW4: INCOME4_SPARSE_OTHERWCHILDREN | AX4: INCOME5_DENSE_SINGLE | AY4: INCOME5_DENSE_SINGLEWCHILDREN | AZ4: INCOME5_DENSE_COUPLE | BA4: INCOME5_DENSE_COUPLEWCHILDREN | BB4: INCOME5_DENSE_OTHER | BC4: INCOME5_DENSE_OTHERWCHILDREN | BD4: INCOME5_SPARSE_SINGLE | BE4: INCOME5_SPARSE_SINGLEWCHILDREN | BF4: INCOME5_SPARSE_COUPLE | BG4: INCOME5_SPARSE_COUPLEWCHILDREN | BH4: INCOME5_SPARSE_OTHER | BI4: INCOME5_SPARSE_OTHERWCHILDREN | BJ4: REPRESENTATIVE_HOUSEHOLD
A5: AUT | B5: 0 | C5: 0 | D5: 0 | E5: 0 | F5: 0 | G5: 0 | H5: 0 | I5: 0 | J5: 0 | K5: 0 | L5: 0 | M5: 0 | N5: 0 | O5: 0 | P5: 0 | Q5: 0 | R5: 0 | S5: 0 | T5: 0 | U5: 0 | V5: 0 | W5: 0 | X5: 0 | Y5: 0 | Z5: 0 | AA5: 0 | AB5: 0 | AC5: 0 | AD5: 0 | AE5: 0 | AF5: 0 | AG5: 0 | AH5: 0 | AI5: 0 | AJ5: 0 | AK5: 0 | AL5: 0 | AM5: 0 | AN5: 0 | AO5: 0 | AP5: 0 | AQ5: 0 | AR5: 0 | AS5: 0 | AT5: 0 | AU5: 0 | AV5: 0 | AW5: 0 | AX5: 0 | AY5: 0 | AZ5: 0 | BA5: 0 | BB5: 0 | BC5: 0 | BD5: 0 | BE5: 0 | BF5: 0 | BG5: 0 | BH5: 0 | BI5: 0 | BJ5: 7905.6854
A6: BEL | B6: 1164.9838 | C6: 909.32097 | D6: 2108.8772 | E6: 909.23729 | F6: 1538.351 | G6: 3537.284 | H6: 1825.2791 | I6: 912.86263 | J6: 4527.7918 | K6: 3092.5088 | L6: 5555.8175 | M6: 2255.4574 | N6: 1897.1255 | O6: 2166.353 | P6: 3264.5235 | Q6: 3509.3084 | R6: 5746.9252 | S6: 3830.0088 | T6: 2759.9298 | U6: 1566.627 | V6: 7353.6076 | W6: 6801.4694 | X6: 7322.5486 | Y6: 7660.2871 | Z6: 1854.1566 | AA6: 2099.0066 | AB6: 7110.1462 | AC6: 5032.8898 | AD6: 9620.9067 | AE6: 4070.5592 | AF6: 4005.4497 | AG6: 2187.4184 | AH6: 7873.3563 | AI6: 8323.6206 | AJ6: 11176.885 | AK6: 6966.9354 | AL6: 3912.2977 | AM6: 1651.3924 | AN6: 7676.1284 | AO6: 7716.1963 | AP6: 7496.3095 | AQ6: 6567.0714 | AR6: 4880.7816 | AS6: 2132.8942 | AT6: 8969.1933 | AU6: 8756.0209 | AV6: 15624.124 | AW6: 9508.8756 | AX6: 6232.3765 | AY6: 7670.3811 | AZ6: 16444.251 | BA6: 11730.93 | BB6: 12856.209 | BC6: 13985.797 | BD6: 6896.3474 | BE6: 4128.8708 | BF6: 14510.482 | BG6: 9089.732 | BH6: 15835.325 | BI6: 16449.28 | BJ6: 0
A7: BGR | B7: 211.88351 | C7: 103.14743 | D7: 383.2624 | E7: 245.23431 | F7: 388.39939 | G7: 433.76392 | H7: 179.29205 | I7: 144.67291 | J7: 254.61776 | K7: 495.63086 | L7: 281.66273 | M7: 494.94006 | N7: 239.77521 | O7: 90.811927 | P7: 385.77702 | Q7: 660.5382 | R7: 507.19804 | S7: 906.11291 | T7: 257.12665 | U7: 303.91293 | V7: 419.70948 | W7: 655.69583 | X7: 494.3632 | Y7: 435.12783 | Z7: 289.32257 | AA7: 139.58795 | AB7: 484.53092 | AC7: 866.4777 | AD7: 4039.7341 | AE7: 964.27774 | AF7: 276.42298 | AG7: 273.24746 | AH7: 522.22505 | AI7: 544.63978 | AJ7: 929.19413 | AK7: 1174.0707 | AL7: 335.79234 | AM7: 249.24609 | AN7: 609.04932 | AO7: 2875.8501 | AP7: 956.09564 | AQ7: 1180.6903 | AR7: 340.92479 | AS7: 577.65662 | AT7: 629.03406 | AU7: 702.31682 | AV7: 728.91074 | AW7: 690.55387 | AX7: 607.40585 | AY7: 411.54552 | AZ7: 1502.2403 | BA7: 1757.8199 | BB7: 1797.7284 | BC7: 2500.5292 | BD7: 469.46828 | BE7: 803.30175 | BF7: 861.84643 | BG7: 1207.5244 | BH7: 1777.558 | BI7: 1941.7139 | BJ7: 0
A8: HRV | B8: 200.68786 | C8: 100.59604 | D8: 409.73461 | E8: 411.76268 | F8: 381.50433 | G8: 280.77637 | H8: 224.16444 | I8: 105.28588 | J8: 270.36495 | K8: 242.6487 | L8: 361.18818 | M8: 478.41808 | N8: 221.20563 | O8: 382.69224 | P8: 332.78597 | Q8: 520.44331 | R8: 784.54987 | S8: 386.97217 | T8: 303.72369 | U8: 270.40788 | V8: 321.98092 | W8: 511.09906 | X8: 528.43355 | Y8: 557.76102 | Z8: 256.41616 | AA8: 165.23179 | AB8: 487.7779 | AC8: 553.9178 | AD8: 610.31673 | AE8: 523.69651 | AF8: 294.94742 | AG8: 293.63117 | AH8: 354.73859 | AI8: 567.35225 | AJ8: 684.08632 | AK8: 748.81432 | AL8: 288.51729 | AM8: 248.95469 | AN8: 611.67789 | AO8: 1658.1365 | AP8: 866.48871 | AQ8: 1105.3764 | AR8: 278.23225 | AS8: 560.70541 | AT8: 568.1422 | AU8: 617.75995 | AV8: 601.79481 | AW8: 951.67954 | AX8: 591.61203 | AY8: 877.83592 | AZ8: 1233.9078 | BA8: 1497.6565 | BB8: 2063.7461 | BC8: 2309.1414 | BD8: 410.09378 | BE8: 770.45904 | BF8: 852.19157 | BG8: 1254.8874 | BH8: 1467.9711 | BI8: 1649.8852 | BJ8: 0
A9: CYP | B9: 814.42375 | C9: 434.60885 | D9: 1442.7189 | E9: 1549.1251 | F9: 3013.4921 | G9: 2940.2419 | H9: 1011.9902 | I9: 790.4435 | J9: 1269.4387 | K9: 1380.9054 | L9: 2145.5313 | M9: 2634.0561 | N9: 1569.4054 | O9: 1005.0792 | P9: 1692.7181 | Q9: 2165.4323 | R9: 3115.5174 | S9: 4307.9268 | T9: 1444.5368 | U9: 1636.5062 | V9: 2073.6523 | W9: 3024.775 | X9: 3123.0816 | Y9: 3126.5393 | Z9: 1716.4049 | AA9: 983.36616 | AB9: 3813.8729 | AC9: 3468.3314 | AD9: 4322.6128 | AE9: 3710.8239 | AF9: 1238.7195 | AG9: 2248.6542 | AH9: 1707.1875 | AI9: 2857.3426 | AJ9: 3493.9756 | AK9: 2171.78 | AL9: 1881.7738 | AM9: 795.5228 | AN9: 3357.5477 | AO9: 7420.6106 | AP9: 6819.5726 | AQ9: 5637.7941 | AR9: 1426.1796 | AS9: 1921.025 | AT9: 2277.4036 | AU9: 3364.9531 | AV9: 4061.2046 | AW9: 3840.6795 | AX9: 5599.8248 | AY9: 3656.1459 | AZ9: 10154.747 | BA9: 6475.0096 | BB9: 10289.164 | BC9: 8886.1563 | BD9: 5214.1168 | BE9: 4172.764 | BF9: 5528.9204 | BG9: 7669.1935 | BH9: 6934.0312 | BI9: 8039.9812 | BJ9: 0
A10: CZE | B10: 429.48546 | C10: 230.62201 | D10: 620.10581 | E10: 743.65739 | F10: 739.9942 | G10: 757.2821 | H10: 425.21748 | I10: 489.54088 | J10: 452.62031 | K10: 865.9322 | L10: 1373.6986 | M10: 614.50348 | N10: 515.86577 | O10: 705.92345 | P10: 659.55202 | Q10: 1068.9564 | R10: 1224.921 | S10: 1367.451 | T10: 545.10201 | U10: 839.62359 | V10: 704.16856 | W10: 1381.2538 | X10: 864.38004 | Y10: 1846.7212 | Z10: 432.8803 | AA10: 362.22094 | AB10: 926.04829 | AC10: 764.2038 | AD10: 1563.0857 | AE10: 1304.8563 | AF10: 345.12673 | AG10: 757.31294 | AH10: 750.30564 | AI10: 1926.1978 | AJ10: 1125.2498 | AK10: 1310.9118 | AL10: 513.2946 | AM10: 584.85669 | AN10: 1616.0344 | AO10: 1668.7112 | AP10: 1758.1165 | AQ10: 2159.7701 | AR10: 624.30721 | AS10: 880.63414 | AT10: 1190.3502 | AU10: 963.80601 | AV10: 2060.3277 | AW10: 2647.0554 | AX10: 1059.3792 | AY10: 1749.0891 | AZ10: 2062.002 | BA10: 2570.5338 | BB10: 3354.3487 | BC10: 4342.3774 | BD10: 750.37539 | BE10: 1562.6515 | BF10: 3075.5316 | BG10: 1871.3168 | BH10: 3071.7903 | BI10: 2672.9975 | BJ10: 0
A11: DNK | B11: 1879.4862 | C11: 686.44553 | D11: 1939.9121 | E11: 2101.4411 | F11: 1029.2391 | G11: 2979.8982 | H11: 2042.7877 | I11: 1087.0214 | J11: 2953.6853 | K11: 1393.6007 | L11: 2900.8 | M11: 2544.0771 | N11: 2038.5805 | O11: 1671.7666 | P11: 2006.9445 | Q11: 7490.4236 | R11: 2000.183 | S11: 3030.5493 | T11: 2491.0172 | U11: 723.68833 | V11: 3673.6902 | W11: 2754.7353 | X11: 4006.7148 | Y11: 3080.8427 | Z11: 3225.0066 | AA11: 1608.3578 | AB11: 9237.6039 | AC11: 9855.1025 | AD11: 3596.7101 | AE11: 3467.7233 | AF11: 3294.8943 | AG11: 1988.1858 | AH11: 6298.2487 | AI11: 3823.7975 | AJ11: 5290.7617 | AK11: 5807.8803 | AL11: 3862.9016 | AM11: 1239.145 | AN11: 6540.6316 | AO11: 26854.747 | AP11: 24835.238 | AQ11: 7053.8553 | AR11: 3276.8612 | AS11: 917.07638 | AT11: 6326.8941 | AU11: 5086.8386 | AV11: 7723.447 | AW11: 5292.0576 | AX11: 11547.78 | AY11: 5802.2464 | AZ11: 18120.933 | BA11: 47389.078 | BB11: 17347.022 | BC11: 15975.154 | BD11: 9869.1826 | BE11: 4342.1568 | BF11: 23917.358 | BG11: 15448.822 | BH11: 27799.75 | BI11: 13011.763 | BJ11: 0
A12: EST | B12: 620.82679 | C12: 354.43607 | D12: 924.12225 | E12: 1124.7457 | F12: 1107.9452 | G12: 1163.0627 | H12: 615.21166 | I12: 710.83328 | J12: 659.86389 | K12: 1312.6782 | L12: 1991.4488 | M12: 952.18096 | N12: 738.34497 | O12: 984.84538 | P12: 979.51753 | Q12: 1596.9412 | R12: 1837.9467 | S12: 2073.9517 | T12: 756.99778 | U12: 1221.6264 | V12: 1044.462 | W12: 2167.9436 | X12: 1292.5826 | Y12: 2893.5221 | Z12: 631.34829 | AA12: 547.00663 | AB12: 1366.0249 | AC12: 1168.1086 | AD12: 2401.9097 | AE12: 1939.876 | AF12: 486.47875 | AG12: 1070.0461 | AH12: 1114.3861 | AI12: 3022.3022 | AJ12: 1690.5781 | AK12: 1951.1351 | AL12: 778.1821 | AM12: 907.08801 | AN12: 2374.4717 | AO12: 2491.7478 | AP12: 2724.093 | AQ12: 3206.5614 | AR12: 912.42726 | AS12: 1317.0629 | AT12: 1785.4138 | AU12: 1484.8797 | AV12: 3083.1834 | AW12: 3869.8423 | AX12: 1594.625 | AY12: 2534.3625 | AZ12: 3054.164 | BA12: 3777.2911 | BB12: 5041.6456 | BC12: 6348.2759 | BD12: 1102.0061 | BE12: 2286.4129 | BF12: 4583.3182 | BG12: 2837.1919 | BH12: 4545.9299 | BI12: 3911.403 | BJ12: 0
A13: FIN | B13: 373.97646 | C13: 408.2127 | D13: 638.42808 | E13: 1516.8019 | F13: 2611.8393 | G13: 2002.6595 | H13: 823.68641 | I13: 693.1036 | J13: 2015.7764 | K13: 2341.9247 | L13: 3666.6689 | M13: 4556.1662 | N13: 813.29514 | O13: 1110.0072 | P13: 1794.0075 | Q13: 2537.3707 | R13: 4792.1748 | S13: 3721.4626 | T13: 1078.3289 | U13: 1315.8948 | V13: 3053.7502 | W13: 2853.7682 | X13: 5030.9248 | Y13: 3871.2754 | Z13: 1103.5089 | AA13: 743.65319 | AB13: 3249.9131 | AC13: 3252.1773 | AD13: 5277.9516 | AE13: 4155.5006 | AF13: 1373.1387 | AG13: 1264.2613 | AH13: 3767.3429 | AI13: 3676.4838 | AJ13: 6184.5737 | AK13: 4254.7581 | AL13: 1844.0387 | AM13: 735.41685 | AN13: 4832.0292 | AO13: 4633.9854 | AP13: 7053.9577 | AQ13: 4606.1328 | AR13: 2095.242 | AS13: 1778.8318 | AT13: 4290.0137 | AU13: 4007.6648 | AV13: 5353.6211 | AW13: 4853.3975 | AX13: 5244.2684 | AY13: 2950.7669 | AZ13: 14768.604 | BA13: 8138.5544 | BB13: 17003.093 | BC13: 18850.582 | BD13: 4251.5634 | BE13: 2605.3476 | BF13: 8967.4679 | BG13: 6666.3117 | BH13: 9219.62 | BI13: 8567.1292 | BJ13: 0
A14: FRA | B14: 759.90747 | C14: 284.31917 | D14: 1179.2891 | E14: 675.74917 | F14: 2550.2437 | G14: 1590.8349 | H14: 1056.8799 | I14: 447.50329 | J14: 1894.0848 | K14: 687.2641 | L14: 2218.724 | M14: 2184.1865 | N14: 812.04867 | O14: 658.91669 | P14: 1498.3261 | Q14: 1648.1037 | R14: 3646.8588 | S14: 2095.1175 | T14: 1079.5975 | U14: 826.2544 | V14: 1994.8422 | W14: 1591.9661 | X14: 2695.7656 | Y14: 2381.5755 | Z14: 1178.0078 | AA14: 639.00924 | AB14: 2024.6697 | AC14: 2901.6652 | AD14: 4521.1625 | AE14: 3017.2969 | AF14: 1913.2223 | AG14: 825.07835 | AH14: 2613.4269 | AI14: 2194.2272 | AJ14: 4439.5821 | AK14: 3062.3568 | AL14: 1930.994 | AM14: 475.38524 | AN14: 4318.2371 | AO14: 3319.3407 | AP14: 6400.2615 | AQ14: 4666.643 | AR14: 1791.1716 | AS14: 1013.6507 | AT14: 3272.4748 | AU14: 3023.4931 | AV14: 4217.4171 | AW14: 3508.0558 | AX14: 9704.8439 | AY14: 1896.9817 | AZ14: 23960.741 | BA14: 8319.2619 | BB14: 11905.133 | BC14: 31594.11 | BD14: 4864.82 | BE14: 1597.0277 | BF14: 9296.6079 | BG14: 6866.16 | BH14: 8018.402 | BI14: 10047.244 | BJ14: 0
A15: DEU | B15: 3489.4028 | C15: 1236.5754 | D15: 2484.0521 | E15: 1804.6885 | F15: 6016.2709 | G15: 2163.1237 | H15: 2522.7172 | I15: 1281.8235 | J15: 3702.4516 | K15: 1892.0376 | L15: 4129.9243 | M15: 3967.6337 | N15: 2838.4058 | O15: 2728.5449 | P15: 3424.3566 | Q15: 3230.784 | R15: 5018.7296 | S15: 4176.8995 | T15: 3277.1757 | U15: 1751.1384 | V15: 3834.0497 | W15: 2981.7408 | X15: 5512.2356 | Y15: 4651.0168 | Z15: 3371.2934 | AA15: 2712.0723 | AB15: 4981.8198 | AC15: 5203.2081 | AD15: 10273.287 | AE15: 5785.421 | AF15: 4948.6661 | AG15: 2529.8789 | AH15: 5427.3297 | AI15: 4301.5899 | AJ15: 7159.3873 | AK15: 5858.3819 | AL15: 5883.5552 | AM15: 2290.4663 | AN15: 9248.9752 | AO15: 28842.781 | AP15: 22201.96 | AQ15: 8865.3851 | AR15: 4101.4463 | AS15: 1756.6607 | AT15: 7262.4575 | AU15: 5785.8976 | AV15: 9165.6234 | AW15: 6821.4908 | AX15: 23657.465 | AY15: 10359.854 | AZ15: 50798.325 | BA15: 20409.023 | BB15: 37671.599 | BC15: 80348.42 | BD15: 12248.61 | BE15: 4777.0444 | BF15: 44517.921 | BG15: 19373.034 | BH15: 25094.538 | BI15: 25157.516 | BJ15: 0
A16: GRC | B16: 529.38466 | C16: 502.90144 | D16: 906.56073 | E16: 954.39621 | F16: 1042.1631 | G16: 713.81001 | H16: 757.16202 | I16: 702.06998 | J16: 1020.653 | K16: 1139.9535 | L16: 1586.6413 | M16: 1572.3932 | N16: 812.62011 | O16: 1200.3305 | P16: 1248.0617 | Q16: 1030.9093 | R16: 1532.5594 | S16: 1233.3286 | T16: 974.81143 | U16: 1321.7515 | V16: 1442.927 | W16: 1633.9352 | X16: 1622.0106 | Y16: 1904.9222 | Z16: 911.2535 | AA16: 908.63988 | AB16: 1672.0683 | AC16: 2084.5018 | AD16: 2034.7613 | AE16: 1237.1498 | AF16: 845.49564 | AG16: 1284.827 | AH16: 1460.716 | AI16: 1899.3989 | AJ16: 2173.2146 | AK16: 2434.9255 | AL16: 1069.5044 | AM16: 896.52981 | AN16: 2261.091 | AO16: 2050.9296 | AP16: 3107.6839 | AQ16: 2524.5398 | AR16: 1122.8777 | AS16: 1737.3668 | AT16: 2001.8257 | AU16: 2083.587 | AV16: 2589.0431 | AW16: 2361.6409 | AX16: 2113.4872 | AY16: 3383.5449 | AZ16: 3311.8941 | BA16: 4934.1171 | BB16: 4015.164 | BC16: 3614.699 | BD16: 1726.6338 | BE16: 2598.3548 | BF16: 3071.9238 | BG16: 3772.7623 | BH16: 3903.2445 | BI16: 6008.9313 | BJ16: 0
... A39: LROW | B39: 0 | C39: 0 | D39: 0 | E39: 0 | F39: 0 | G39: 0 | H39: 0 | I39: 0 | J39: 0 | K39: 0 | L39: 0 | M39: 0 | N39: 0 | O39: 0 | P39: 0 | Q39: 0 | R39: 0 | S39: 0 | T39: 0 | U39: 0 | V39: 0 | W39: 0 | X39: 0 | Y39: 0 | Z39: 0 | AA39: 0 | AB39: 0 | AC39: 0 | AD39: 0 | AE39: 0 | AF39: 0 | AG39: 0 | AH39: 0 | AI39: 0 | AJ39: 0 | AK39: 0 | AL39: 0 | AM39: 0 | AN39: 0 | AO39: 0 | AP39: 0 | AQ39: 0 | AR39: 0 | AS39: 0 | AT39: 0 | AU39: 0 | AV39: 0 | AW39: 0 | AX39: 0 | AY39: 0 | AZ39: 0 | BA39: 0 | BB39: 0 | BC39: 0 | BD39: 0 | BE39: 0 | BF39: 0 | BG39: 0 | BH39: 0 | BI39: 0 | BJ39: 120.71603

Sheet HH_Property_income_paid
B4: INCOME1_DENSE_SINGLE | C4: INCOME1_DENSE_SINGLEWCHILDREN | D4: INCOME1_DENSE_COUPLE | E4: INCOME1_DENSE_COUPLEWCHILDREN | F4: INCOME1_DENSE_OTHER | G4: INCOME1_DENSE_OTHERWCHILDREN | H4: INCOME1_SPARSE_SINGLE | I4: INCOME1_SPARSE_SINGLEWCHILDREN | J4: INCOME1_SPARSE_COUPLE | K4: INCOME1_SPARSE_COUPLEWCHILDREN | L4: INCOME1_SPARSE_OTHER | M4: INCOME1_SPARSE_OTHERWCHILDREN | N4: INCOME2_DENSE_SINGLE | O4: INCOME2_DENSE_SINGLEWCHILDREN | P4: INCOME2_DENSE_COUPLE | Q4: INCOME2_DENSE_COUPLEWCHILDREN | R4: INCOME2_DENSE_OTHER | S4: INCOME2_DENSE_OTHERWCHILDREN | T4: INCOME2_SPARSE_SINGLE | U4: INCOME2_SPARSE_SINGLEWCHILDREN | V4: INCOME2_SPARSE_COUPLE | W4: INCOME2_SPARSE_COUPLEWCHILDREN | X4: INCOME2_SPARSE_OTHER | Y4: INCOME2_SPARSE_OTHERWCHILDREN | Z4: INCOME3_DENSE_SINGLE | AA4: INCOME3_DENSE_SINGLEWCHILDREN | AB4: INCOME3_DENSE_COUPLE | AC4: INCOME3_DENSE_COUPLEWCHILDREN | AD4: INCOME3_DENSE_OTHER | AE4: INCOME3_DENSE_OTHERWCHILDREN | AF4: INCOME3_SPARSE_SINGLE | AG4: INCOME3_SPARSE_SINGLEWCHILDREN | AH4: INCOME3_SPARSE_COUPLE | AI4: INCOME3_SPARSE_COUPLEWCHILDREN | AJ4: INCOME3_SPARSE_OTHER | AK4: INCOME3_SPARSE_OTHERWCHILDREN | AL4: INCOME4_DENSE_SINGLE | AM4: INCOME4_DENSE_SINGLEWCHILDREN | AN4: INCOME4_DENSE_COUPLE | AO4: INCOME4_DENSE_COUPLEWCHILDREN | AP4: INCOME4_DENSE_OTHER | AQ4: INCOME4_DENSE_OTHERWCHILDREN | AR4: INCOME4_SPARSE_SINGLE | AS4: INCOME4_SPARSE_SINGLEWCHILDREN | AT4: INCOME4_SPARSE_COUPLE | AU4: INCOME4_SPARSE_COUPLEWCHILDREN | AV4: INCOME4_SPARSE_OTHER | AW4: INCOME4_SPARSE_OTHERWCHILDREN | AX4: INCOME5_DENSE_SINGLE | AY4: INCOME5_DENSE_SINGLEWCHILDREN | AZ4: INCOME5_DENSE_COUPLE | BA4: INCOME5_DENSE_COUPLEWCHILDREN | BB4: INCOME5_DENSE_OTHER | BC4: INCOME5_DENSE_OTHERWCHILDREN | BD4: INCOME5_SPARSE_SINGLE | BE4: INCOME5_SPARSE_SINGLEWCHILDREN | BF4: INCOME5_SPARSE_COUPLE | BG4: INCOME5_SPARSE_COUPLEWCHILDREN | BH4: INCOME5_SPARSE_OTHER | BI4: INCOME5_SPARSE_OTHERWCHILDREN | BJ4: REPRESENTATIVE_HOUSEHOLD
A5: AUT | B5: 0 | C5: 0 | D5: 0 | E5: 0 | F5: 0 | G5: 0 | H5: 0 | I5: 0 | J5: 0 | K5: 0 | L5: 0 | M5: 0 | N5: 0 | O5: 0 | P5: 0 | Q5: 0 | R5: 0 | S5: 0 | T5: 0 | U5: 0 | V5: 0 | W5: 0 | X5: 0 | Y5: 0 | Z5: 0 | AA5: 0 | AB5: 0 | AC5: 0 | AD5: 0 | AE5: 0 | AF5: 0 | AG5: 0 | AH5: 0 | AI5: 0 | AJ5: 0 | AK5: 0 | AL5: 0 | AM5: 0 | AN5: 0 | AO5: 0 | AP5: 0 | AQ5: 0 | AR5: 0 | AS5: 0 | AT5: 0 | AU5: 0 | AV5: 0 | AW5: 0 | AX5: 0 | AY5: 0 | AZ5: 0 | BA5: 0 | BB5: 0 | BC5: 0 | BD5: 0 | BE5: 0 | BF5: 0 | BG5: 0 | BH5: 0 | BI5: 0 | BJ5: 481.78451
A6: BEL | B6: 33.953954 | C6: 353.36577 | D6: 86.456648 | E6: 171.31109 | F6: 99.516393 | G6: 155.48172 | H6: 158.61597 | I6: 208.55394 | J6: 124.30246 | K6: 804.74378 | L6: 398.31155 | M6: 508.98545 | N6: 140.47116 | O6: 174.02862 | P6: 267.19113 | Q6: 435.43468 | R6: 506.33484 | S6: 263.07079 | T6: 163.18333 | U6: 348.09019 | V6: 258.73301 | W6: 1349.8997 | X6: 521.40219 | Y6: 648.85944 | Z6: 188.59721 | AA6: 291.17001 | AB6: 356.79989 | AC6: 1194.6258 | AD6: 318.21253 | AE6: 601.74545 | AF6: 271.68476 | AG6: 224.86526 | AH6: 407.68072 | AI6: 1829.2158 | AJ6: 616.38386 | AK6: 900.03421 | AL6: 357.73778 | AM6: 399.37609 | AN6: 621.2217 | AO6: 1669.2717 | AP6: 302.99459 | AQ6: 1006.4756 | AR6: 319.08022 | AS6: 405.37758 | AT6: 489.87636 | AU6: 1558.5807 | AV6: 2507.8527 | AW6: 1228.3238 | AX6: 469.80582 | AY6: 150.7434 | AZ6: 457.54523 | BA6: 1322.3892 | BB6: 121.87346 | BC6: 1556.7157 | BD6: 273.84509 | BE6: 792.74899 | BF6: 343.29504 | BG6: 1165.5467 | BH6: 356.93252 | BI6: 1233.6052 | BJ6: 0
A7: BGR | B7: 151.80714 | C7: 8.573292 | D7: 64.825029 | E7: 53.696973 | F7: 64.159877 | G7: 48.926762 | H7: 88.241398 | I7: 28.495111 | J7: 68.640798 | K7: 112.76193 | L7: 118.00749 | M7: 128.13419 | N7: 44.941212 | O7: 11.582897 | P7: 108.86185 | Q7: 189.57554 | R7: 260.97327 | S7: 140.36886 | T7: 144.49375 | U7: 65.355129 | V7: 112.66157 | W7: 144.87246 | X7: 136.33382 | Y7: 175.18138 | Z7: 63.275161 | AA7: 1.6687288 | AB7: 171.43655 | AC7: 286.46509 | AD7: 253.07771 | AE7: 200.56891 | AF7: 97.402845 | AG7: 102.21515 | AH7: 91.003046 | AI7: 148.64405 | AJ7: 168.23593 | AK7: 170.80049 | AL7: 100.17659 | AM7: 2.4698504 | AN7: 110.47834 | AO7: 133.19421 | AP7: 322.71628 | AQ7: 272.10539 | AR7: 59.769883 | AS7: 139.07517 | AT7: 139.63544 | AU7: 173.97775 | AV7: 176.53897 | AW7: 295.41867 | AX7: 81.011725 | AY7: 173.63941 | AZ7: 271.88494 | BA7: 241.82275 | BB7: 369.40908 | BC7: 579.62763 | BD7: 98.54281 | BE7: 175.93518 | BF7: 157.48474 | BG7: 163.69147 | BH7: 441.21876 | BI7: 198.42519 | BJ7: 0
A8: HRV | B8: 54.087136 | C8: 144.73614 | D8: 57.731513 | E8: 218.626 | F8: 159.68843 | G8: 159.33187 | H8: 33.032526 | I8: 0 | J8: 73.981018 | K8: 133.22558 | L8: 110.28032 | M8: 188.67831 | N8: 110.41949 | O8: 405.58593 | P8: 195.64794 | Q8: 421.04778 | R8: 359.50342 | S8: 408.80873 | T8: 37.778868 | U8: 115.70121 | V8: 61.282499 | W8: 249.64543 | X8: 314.50228 | Y8: 96.846964 | Z8: 133.36785 | AA8: 113.24773 | AB8: 317.64648 | AC8: 397.80846 | AD8: 346.81011 | AE8: 200.10012 | AF8: 57.483117 | AG8: 238.75334 | AH8: 154.63556 | AI8: 371.9808 | AJ8: 317.77231 | AK8: 430.7002 | AL8: 47.525116 | AM8: 500.71668 | AN8: 376.82211 | AO8: 425.44005 | AP8: 410.97535 | AQ8: 317.07514 | AR8: 91.886461 | AS8: 361.80547 | AT8: 282.32597 | AU8: 470.9663 | AV8: 551.28033 | AW8: 352.11601 | AX8: 291.71064 | AY8: 509.32004 | AZ8: 937.8113 | BA8: 1158.0172 | BB8: 396.61687 | BC8: 1382.5161 | BD8: 91.398777 | BE8: 484.85761 | BF8: 729.53771 | BG8: 798.39357 | BH8: 585.5893 | BI8: 637.32456 | BJ8: 0
A9: CYP | B9: 242.14295 | C9: 1182.5009 | D9: 426.25974 | E9: 1049.6104 | F9: 974.92305 | G9: 1240.1375 | H9: 282.90311 | I9: 305.28025 | J9: 459.99551 | K9: 708.90737 | L9: 1021.3562 | M9: 910.79052 | N9: 416.45366 | O9: 582.36822 | P9: 458.78398 | Q9: 854.31314 | R9: 1271.189 | S9: 1764.2869 | T9: 364.42514 | U9: 184.71194 | V9: 566.31319 | W9: 943.54589 | X9: 813.06314 | Y9: 895.03576 | Z9: 307.01061 | AA9: 974.3694 | AB9: 1195.3598 | AC9: 1213.1634 | AD9: 1407.3649 | AE9: 1241.5434 | AF9: 271.37648 | AG9: 876.55012 | AH9: 858.55237 | AI9: 1121.425 | AJ9: 1223.414 | AK9: 1186.4897 | AL9: 485.70181 | AM9: 1336.4695 | AN9: 1095.2643 | AO9: 1872.4771 | AP9: 1257.7104 | AQ9: 1675.6174 | AR9: 162.92839 | AS9: 326.41806 | AT9: 713.31361 | AU9: 808.69102 | AV9: 1799.0714 | AW9: 2387.9142 | AX9: 751.55149 | AY9: 504.44672 | AZ9: 1893.8277 | BA9: 2122.6648 | BB9: 1342.1451 | BC9: 2531.8916 | BD9: 575.52225 | BE9: 997.27569 | BF9: 1224.7193 | BG9: 1337.0295 | BH9: 2174.3557 | BI9: 1824.7141 | BJ9: 0
A10: CZE | B10: 47.079835 | C10: 220.64371 | D10: 79.268003 | E10: 249.56065 | F10: 108.07156 | G10: 32.018516 | H10: 30.229487 | I10: 43.362282 | J10: 64.432644 | K10: 184.17426 | L10: 95.65206 | M10: 118.4919 | N10: 1.1507293 | O10: 108.66451 | P10: 33.163857 | Q10: 228.60936 | R10: 111.0438 | S10: 91.859801 | T10: 43.407633 | U10: 81.834122 | V10: 73.96059 | W10: 214.61499 | X10: 147.71566 | Y10: 140.69511 | Z10: 36.411946 | AA10: 181.8083 | AB10: 44.387194 | AC10: 278.17155 | AD10: 271.72296 | AE10: 131.25575 | AF10: 58.028886 | AG10: 120.30596 | AH10: 76.298849 | AI10: 252.56904 | AJ10: 169.468 | AK10: 177.59767 | AL10: 82.09082 | AM10: 249.37283 | AN10: 93.336368 | AO10: 252.39194 | AP10: 324.77497 | AQ10: 178.07046 | AR10: 64.014852 | AS10: 158.7778 | AT10: 61.10954 | AU10: 240.02989 | AV10: 105.62808 | AW10: 379.39474 | AX10: 250.77425 | AY10: 94.125085 | AZ10: 221.31376 | BA10: 675.98547 | BB10: 185.49599 | BC10: 379.31831 | BD10: 68.84205 | BE10: 197.24964 | BF10: 122.72388 | BG10: 327.36362 | BH10: 232.17996 | BI10: 369.7872 | BJ10: 0
A11: DNK | B11: 1072.0727 | C11: 1725.8077 | D11: 942.85995 | E11: 589.27252 | F11: 1444.9279 | G11: 1992.2813 | H11: 679.87251 | I11: 1336.4972 | J11: 777.96645 | K11: 1172.4114 | L11: 1766.5007 | M11: 1137.0346 | N11: 1206.8115 | O11: 849.94064 | P11: 1883.0148 | Q11: 1132.5179 | R11: 1884.022 | S11: 2834.3276 | T11: 1553.0981 | U11: 808.65693 | V11: 2301.843 | W11: 3800.794 | X11: 1337.9718 | Y11: 2590.6629 | Z11: 903.95613 | AA11: 1422.049 | AB11: 1290.2184 | AC11: 2583.917 | AD11: 2085.8476 | AE11: 1994.54 | AF11: 1557.1238 | AG11: 3837.4797 | AH11: 1629.1304 | AI11: 5551.6705 | AJ11: 1758.8961 | AK11: 6307.1462 | AL11: 3309.4266 | AM11: 1950.5181 | AN11: 2431.6385 | AO11: 3647.5743 | AP11: 1864.0455 | AQ11: 2691.88 | AR11: 1299.275 | AS11: 1429.0371 | AT11: 3222.9705 | AU11: 4410.1483 | AV11: 2257.7299 | AW11: 3234.8578 | AX11: 1624.2241 | AY11: 736.21767 | AZ11: 4781.0951 | BA11: 11861.174 | BB11: 1989.1856 | BC11: 4067.4849 | BD11: 2189.5275 | BE11: 4366.0084 | BF11: 3701.6526 | BG11: 5438.4863 | BH11: 2642.0576 | BI11: 4723.0105 | BJ11: 0
